Workbook

Sheet Data Dashboard
A1: Data Dashboard — Master Franchise Data (source of truth for all formulas in this workbook)
A4: Team | B4: 2025 Brand Value ($M) | C4: 2026 Brand Value ($M) | D4: Titles | E4: Playoff Appearances | F4: Finals Reached | G4: All-Time Win% (2008-23) | H4: All-Time Matches (2008-23) | I4: All-Time Wins | J4: All-Time Losses | K4: Home City GDP ($B) | L4: Population (2011 Census) | M4: Instagram Followers (M) | N4: X Followers (M) | O4: Social Followers Total (M) | P4: 2025 Auction Spend (₹Cr) | Q4: Founded Year | R4: Franchise Era | S4: Title Tier
A5: Chennai Super Kings | B5: 235 | C5: 244 | D5: 5 | E5: 12 | F5: 10 | G5: 57 | H5: 200 | I5: 114 | J5: 83 | K5: 91.53 | L5: 4646732 | M5: 23.4 | N5: 10.9 | O5: =M5+N5 -> 34.3 | P5: 119.95 | Q5: 2008 | R5: =IF(Q5>=2022,"Expansion","Legacy") -> Legacy | S5: =IF(D5=0,"Zero titles",IF(D5=1,"Single title","Multiple titles")) -> Multiple titles
A6: Mumbai Indians | B6: 242 | C6: 264 | D6: 5 | E6: 11 | F6: 6 | G6: 55.7 | H6: 228 | I6: 127 | J6: 100 | K6: 162.44 | L6: 12442373 | M6: 19.9 | N6: 8.3 | O6: =M6+N6 -> 28.2 | P6: 119.8 | Q6: 2008 | R6: =IF(Q6>=2022,"Expansion","Legacy") -> Legacy | S6: =IF(D6=0,"Zero titles",IF(D6=1,"Single title","Multiple titles")) -> Multiple titles
A7: Royal Challengers Bengaluru | B7: 269 | C7: 312 | D7: 2 | E7: 11 | F7: 5 | G7: 48.25 | H7: 228 | I7: 110 | J7: 112 | K7: 112.42 | L7: 8443675 | M7: 24.4 | N7: 7.4 | O7: =M7+N7 -> 31.8 | P7: 119.7 | Q7: 2008 | R7: =IF(Q7>=2022,"Expansion","Legacy") -> Legacy | S7: =IF(D7=0,"Zero titles",IF(D7=1,"Single title","Multiple titles")) -> Multiple titles
A8: Kolkata Knight Riders | B8: 227 | C8: 245 | D8: 3 | E8: 8 | F8: 4 | G8: 49.12 | H8: 228 | I8: 112 | J8: 112 | K8: 75.21 | L8: 4496694 | M8: 7.9 | N8: 5.3 | O8: =M8+N8 -> 13.2 | P8: 119.95 | Q8: 2008 | R8: =IF(Q8>=2022,"Expansion","Legacy") -> Legacy | S8: =IF(D8=0,"Zero titles",IF(D8=1,"Single title","Multiple titles")) -> Multiple titles
A9: Sunrisers Hyderabad | B9: 154 | C9: 168 | D9: 1 | E9: 8 | F9: 3 | G9: 47.44 | H9: 156 | I9: 74 | J9: 81 | K9: 80.06 | L9: 6731790 | M9: 5.8 | N9: 3.3 | O9: =M9+N9 -> 9.1 | P9: 119.85 | Q9: 2013 | R9: =IF(Q9>=2022,"Expansion","Legacy") -> Legacy | S9: =IF(D9=0,"Zero titles",IF(D9=1,"Single title","Multiple titles")) -> Single title
A10: Rajasthan Royals | B10: 146 | C10: 161 | D10: 1 | E10: 7 | F10: 2 | G10: 49.5 | H10: 200 | I10: 99 | J10: 96 | K10: 18.13 | L10: 3073350 | M10: 6.5 | N10: 2.9 | O10: =M10+N10 -> 9.4 | P10: 119.9 | Q10: 2008 | R10: =IF(Q10>=2022,"Expansion","Legacy") -> Legacy | S10: =IF(D10=0,"Zero titles",IF(D10=1,"Single title","Multiple titles")) -> Single title
A11: Delhi Capitals | B11: 152 | C11: 156 | D11: 0 | E11: 6 | F11: 1 | G11: 46.49 | H11: 228 | I11: 106 | J11: 119 | K11: 186.14 | L11: 16314838 | M11: 4.7 | N11: 2.6 | O11: =M11+N11 -> 7.3 | P11: 119.8 | Q11: 2008 | R11: =IF(Q11>=2022,"Expansion","Legacy") -> Legacy | S11: =IF(D11=0,"Zero titles",IF(D11=1,"Single title","Multiple titles")) -> Zero titles
A12: Punjab Kings | B12: 141 | C12: 158 | D12: 0 | E12: 3 | F12: 2 | G12: 46.49 | H12: 228 | I12: 106 | J12: 122 | K12: 11.7 | L12: 1025682 | M12: 5.3 | N12: 3 | O12: =M12+N12 -> 8.3 | P12: 119.5 | Q12: 2008 | R12: =IF(Q12>=2022,"Expansion","Legacy") -> Legacy | S12: =IF(D12=0,"Zero titles",IF(D12=1,"Single title","Multiple titles")) -> Zero titles
A13: Gujarat Titans | B13: 142 | C13: 157 | D13: 1 | E13: 4 | F13: 3 | G13: 71.43 | H13: 28 | I13: 20 | J13: 8 | K13: 67.28 | L13: 5577940 | M13: 5.1 | N13: 0.621 | O13: =M13+N13 -> 5.721 | P13: 119.85 | Q13: 2022 | R13: =IF(Q13>=2022,"Expansion","Legacy") -> Expansion | S13: =IF(D13=0,"Zero titles",IF(D13=1,"Single title","Multiple titles")) -> Single title
A14: Lucknow Super Giants | B14: 122 | C14: 122 | D14: 0 | E14: 2 | F14: 0 | G14: 60.71 | H14: 28 | I14: 17 | J14: 10 | K14: 10.92 | L14: 2901474 | M14: 3.6 | N14: 0.816 | O14: =M14+N14 -> 4.416 | P14: 119.9 | Q14: 2022 | R14: =IF(Q14>=2022,"Expansion","Legacy") -> Expansion | S14: =IF(D14=0,"Zero titles",IF(D14=1,"Single title","Multiple titles")) -> Zero titles
A17: Blue text = hardcoded input value (sourced from your uploaded data / cited studies).
A18: Black text = live formula (recalculates automatically if a blue input cell changes).
A19: Legacy/Expansion split is by founding year: teams founded 2008 = Legacy (includes SRH, which entered 2013 replacing the defunct Deccan Chargers slot); GT and LSG (2022 entrants) = Expansion.
A38: Data Sources & Limitations
A39: • Y variable (2025 Brand Value): Houlihan Lokey 2025 IPL Brand Valuation Study, team-level figures for all 10 franchises.
A40: • Titles / Playoff Appearances: cross-referenced against IPL official results through the 2026 season.
A41: • All-time win %: aggregated across 16 seasons (2008-2023) of scraped final points tables. Season labels were not present in the source data and were inferred from squad composition (e.g. KTK only existed in 2011, PWI 2011-2013, DCG 2008-2012) — 2024-2026 season tables were not present and are excluded, flagged rather than estimated.
A42: • Home City GDP: metropolitan-area estimates (2022-23); India has no official city-level GDP series, so these are institutional approximations, not government statistics.
A43: • Social followers: Instagram + X follower counts as tracked in late 2025/2026; a point-in-time snapshot, not a time series.
A44: • Auction spend: 2025 mega-auction utilization out of a ₹120 Cr salary cap. Values are nearly identical across teams (₹119.5-120.0 Cr for 9 of 10) — very little cross-team variance for the cap-constrained variable to explain.
A45: • Sample size is n=10 franchises throughout this workbook. All statistical tests should be read as descriptive/directional, not high-power inferential results.
A46: • Every number on this sheet in black text is a hardcoded input (blue font) or a live formula (black font) — see the color legend at the bottom of this sheet's data table. Every other sheet in this workbook references THIS sheet, so editing a blue input cell here recalculates the entire workbook.

Sheet 2. Descriptives & Correlation
A1: Descriptive Statistics & Correlation
A4: 2.1 Descriptive Measures — 2025 Brand Value ($M)
A5: Mean | B5: =AVERAGE('Data Dashboard'!$B$5:$B$14) -> 183
A6: Median | B6: =MEDIAN('Data Dashboard'!$B$5:$B$14) -> 153
A7: Std. Deviation (sample, VAR.S basis) | B7: =_xlfn.STDEV.S('Data Dashboard'!$B$5:$B$14) -> 53.597264
A8: Variance (sample) | B8: =_xlfn.VAR.S('Data Dashboard'!$B$5:$B$14) -> 2872.6667
A9: Min | B9: =MIN('Data Dashboard'!$B$5:$B$14) -> 122
A10: Max | B10: =MAX('Data Dashboard'!$B$5:$B$14) -> 269
A11: N | B11: =COUNT('Data Dashboard'!$B$5:$B$14) -> 10
A13: 2.2 Pearson Correlation: Auction Spend (2025) vs. All-Time Win %
A14: Pearson r | B14: =CORREL('Data Dashboard'!$P$5:$P$14,'Data Dashboard'!$G$5:$G$14) -> 0.35116705
A15: n | B15: =COUNT('Data Dashboard'!$P$5:$P$14) -> 10
A16: t-statistic (= r*SQRT(n-2)/SQRT(1-r^2)) | B16: =B14*SQRT(B15-2)/SQRT(1-B14^2) -> 1.0608104
A17: p-value (two-tailed, df = n-2) | B17: =_xlfn.T.DIST.2T(ABS(B16),B15-2) -> 0.31974908
A19: Interpretation — 'Does money buy wins?': weak and not statistically significant. The 2025 mega-auction salary cap compresses spend into a very narrow band (~₹119.5-120.0 Cr for 9 of 10 teams), leaving almost no cross-team variance for win% to correlate with.
A21: 2.3 Pearson Correlation Matrix
B22: 2025 Brand Value | C22: Titles | D22: Win% (08-23) | E22: City GDP | F22: Social Followers | G22: Auction Spend | H22: Population
A23: 2025 Brand Value | B23: =CORREL('Data Dashboard'!$B$5:$B$14,'Data Dashboard'!$B$5:$B$14) -> 1 | C23: =CORREL('Data Dashboard'!$B$5:$B$14,'Data Dashboard'!$D$5:$D$14) -> 0.80683426 | D23: =CORREL('Data Dashboard'!$B$5:$B$14,'Data Dashboard'!$G$5:$G$14) -> -0.17239932 | E23: =CORREL('Data Dashboard'!$B$5:$B$14,'Data Dashboard'!$K$5:$K$14) -> 0.50379966 | F23: =CORREL('Data Dashboard'!$B$5:$B$14,'Data Dashboard'!$O$5:$O$14) -> 0.91053321 | G23: =CORREL('Data Dashboard'!$B$5:$B$14,'Data Dashboard'!$P$5:$P$14) -> 0.07784886 | H23: =CORREL('Data Dashboard'!$B$5:$B$14,'Data Dashboard'!$L$5:$L$14) -> 0.28094802
A24: Titles | B24: =CORREL('Data Dashboard'!$D$5:$D$14,'Data Dashboard'!$B$5:$B$14) -> 0.80683426 | C24: =CORREL('Data Dashboard'!$D$5:$D$14,'Data Dashboard'!$D$5:$D$14) -> 1 | D24: =CORREL('Data Dashboard'!$D$5:$D$14,'Data Dashboard'!$G$5:$G$14) -> 0.12737599 | E24: =CORREL('Data Dashboard'!$D$5:$D$14,'Data Dashboard'!$K$5:$K$14) -> 0.39828708 | F24: =CORREL('Data Dashboard'!$D$5:$D$14,'Data Dashboard'!$O$5:$O$14) -> 0.83052479 | G24: =CORREL('Data Dashboard'!$D$5:$D$14,'Data Dashboard'!$P$5:$P$14) -> 0.35567685 | H24: =CORREL('Data Dashboard'!$D$5:$D$14,'Data Dashboard'!$L$5:$L$14) -> 0.15956742
A25: Win% (08-23) | B25: =CORREL('Data Dashboard'!$G$5:$G$14,'Data Dashboard'!$B$5:$B$14) -> -0.17239932 | C25: =CORREL('Data Dashboard'!$G$5:$G$14,'Data Dashboard'!$D$5:$D$14) -> 0.12737599 | D25: =CORREL('Data Dashboard'!$G$5:$G$14,'Data Dashboard'!$G$5:$G$14) -> 1 | E25: =CORREL('Data Dashboard'!$G$5:$G$14,'Data Dashboard'!$K$5:$K$14) -> -0.15230108 | F25: =CORREL('Data Dashboard'!$G$5:$G$14,'Data Dashboard'!$O$5:$O$14) -> -0.079561016 | G25: =CORREL('Data Dashboard'!$G$5:$G$14,'Data Dashboard'!$P$5:$P$14) -> 0.35116705 | H25: =CORREL('Data Dashboard'!$G$5:$G$14,'Data Dashboard'!$L$5:$L$14) -> -0.16185975
A26: City GDP | B26: =CORREL('Data Dashboard'!$K$5:$K$14,'Data Dashboard'!$B$5:$B$14) -> 0.50379966 | C26: =CORREL('Data Dashboard'!$K$5:$K$14,'Data Dashboard'!$D$5:$D$14) -> 0.39828708 | D26: =CORREL('Data Dashboard'!$K$5:$K$14,'Data Dashboard'!$G$5:$G$14) -> -0.15230108 | E26: =CORREL('Data Dashboard'!$K$5:$K$14,'Data Dashboard'!$K$5:$K$14) -> 1 | F26: =CORREL('Data Dashboard'!$K$5:$K$14,'Data Dashboard'!$O$5:$O$14) -> 0.43065069 | G26: =CORREL('Data Dashboard'!$K$5:$K$14,'Data Dashboard'!$P$5:$P$14) -> 0.057227312 | H26: =CORREL('Data Dashboard'!$K$5:$K$14,'Data Dashboard'!$L$5:$L$14) -> 0.95372786
A27: Social Followers | B27: =CORREL('Data Dashboard'!$O$5:$O$14,'Data Dashboard'!$B$5:$B$14) -> 0.91053321 | C27: =CORREL('Data Dashboard'!$O$5:$O$14,'Data Dashboard'!$D$5:$D$14) -> 0.83052479 | D27: =CORREL('Data Dashboard'!$O$5:$O$14,'Data Dashboard'!$G$5:$G$14) -> -0.079561016 | E27: =CORREL('Data Dashboard'!$O$5:$O$14,'Data Dashboard'!$K$5:$K$14) -> 0.43065069 | F27: =CORREL('Data Dashboard'!$O$5:$O$14,'Data Dashboard'!$O$5:$O$14) -> 1 | G27: =CORREL('Data Dashboard'!$O$5:$O$14,'Data Dashboard'!$P$5:$P$14) -> 0.038460468 | H27: =CORREL('Data Dashboard'!$O$5:$O$14,'Data Dashboard'!$L$5:$L$14) -> 0.21390492
A28: Auction Spend | B28: =CORREL('Data Dashboard'!$P$5:$P$14,'Data Dashboard'!$B$5:$B$14) -> 0.07784886 | C28: =CORREL('Data Dashboard'!$P$5:$P$14,'Data Dashboard'!$D$5:$D$14) -> 0.35567685 | D28: =CORREL('Data Dashboard'!$P$5:$P$14,'Data Dashboard'!$G$5:$G$14) -> 0.35116705 | E28: =CORREL('Data Dashboard'!$P$5:$P$14,'Data Dashboard'!$K$5:$K$14) -> 0.057227312 | F28: =CORREL('Data Dashboard'!$P$5:$P$14,'Data Dashboard'!$O$5:$O$14) -> 0.038460468 | G28: =CORREL('Data Dashboard'!$P$5:$P$14,'Data Dashboard'!$P$5:$P$14) -> 1 | H28: =CORREL('Data Dashboard'!$P$5:$P$14,'Data Dashboard'!$L$5:$L$14) -> 0.020792147
A29: Population | B29: =CORREL('Data Dashboard'!$L$5:$L$14,'Data Dashboard'!$B$5:$B$14) -> 0.28094802 | C29: =CORREL('Data Dashboard'!$L$5:$L$14,'Data Dashboard'!$D$5:$D$14) -> 0.15956742 | D29: =CORREL('Data Dashboard'!$L$5:$L$14,'Data Dashboard'!$G$5:$G$14) -> -0.16185975 | E29: =CORREL('Data Dashboard'!$L$5:$L$14,'Data Dashboard'!$K$5:$K$14) -> 0.95372786 | F29: =CORREL('Data Dashboard'!$L$5:$L$14,'Data Dashboard'!$O$5:$O$14) -> 0.21390492 | G29: =CORREL('Data Dashboard'!$L$5:$L$14,'Data Dashboard'!$P$5:$P$14) -> 0.020792147 | H29: =CORREL('Data Dashboard'!$L$5:$L$14,'Data Dashboard'!$L$5:$L$14) -> 1
A31: 2.4 Spearman Rank Correlation: Win% Rank vs. Brand Value Rank
A32: Per-team ranks (RANK.AVG, descending = rank 1 is best)
A33: Team | B33: Win% Rank | C33: Brand Value Rank
A34: ='Data Dashboard'!A5 -> Chennai Super Kings | B34: =_xlfn.RANK.AVG('Data Dashboard'!G5,'Data Dashboard'!$G$5:$G$14) -> 3 | C34: =_xlfn.RANK.AVG('Data Dashboard'!B5,'Data Dashboard'!$B$5:$B$14) -> 3
A35: ='Data Dashboard'!A6 -> Mumbai Indians | B35: =_xlfn.RANK.AVG('Data Dashboard'!G6,'Data Dashboard'!$G$5:$G$14) -> 4 | C35: =_xlfn.RANK.AVG('Data Dashboard'!B6,'Data Dashboard'!$B$5:$B$14) -> 2
A36: ='Data Dashboard'!A7 -> Royal Challengers Bengaluru | B36: =_xlfn.RANK.AVG('Data Dashboard'!G7,'Data Dashboard'!$G$5:$G$14) -> 7 | C36: =_xlfn.RANK.AVG('Data Dashboard'!B7,'Data Dashboard'!$B$5:$B$14) -> 1
A37: ='Data Dashboard'!A8 -> Kolkata Knight Riders | B37: =_xlfn.RANK.AVG('Data Dashboard'!G8,'Data Dashboard'!$G$5:$G$14) -> 6 | C37: =_xlfn.RANK.AVG('Data Dashboard'!B8,'Data Dashboard'!$B$5:$B$14) -> 4
A38: ='Data Dashboard'!A9 -> Sunrisers Hyderabad | B38: =_xlfn.RANK.AVG('Data Dashboard'!G9,'Data Dashboard'!$G$5:$G$14) -> 8 | C38: =_xlfn.RANK.AVG('Data Dashboard'!B9,'Data Dashboard'!$B$5:$B$14) -> 5
A39: ='Data Dashboard'!A10 -> Rajasthan Royals | B39: =_xlfn.RANK.AVG('Data Dashboard'!G10,'Data Dashboard'!$G$5:$G$14) -> 5 | C39: =_xlfn.RANK.AVG('Data Dashboard'!B10,'Data Dashboard'!$B$5:$B$14) -> 7
A40: ='Data Dashboard'!A11 -> Delhi Capitals | B40: =_xlfn.RANK.AVG('Data Dashboard'!G11,'Data Dashboard'!$G$5:$G$14) -> 9.5 | C40: =_xlfn.RANK.AVG('Data Dashboard'!B11,'Data Dashboard'!$B$5:$B$14) -> 6
A41: ='Data Dashboard'!A12 -> Punjab Kings | B41: =_xlfn.RANK.AVG('Data Dashboard'!G12,'Data Dashboard'!$G$5:$G$14) -> 9.5 | C41: =_xlfn.RANK.AVG('Data Dashboard'!B12,'Data Dashboard'!$B$5:$B$14) -> 9
A42: ='Data Dashboard'!A13 -> Gujarat Titans | B42: =_xlfn.RANK.AVG('Data Dashboard'!G13,'Data Dashboard'!$G$5:$G$14) -> 1 | C42: =_xlfn.RANK.AVG('Data Dashboard'!B13,'Data Dashboard'!$B$5:$B$14) -> 8
A43: ='Data Dashboard'!A14 -> Lucknow Super Giants | B43: =_xlfn.RANK.AVG('Data Dashboard'!G14,'Data Dashboard'!$G$5:$G$14) -> 2 | C43: =_xlfn.RANK.AVG('Data Dashboard'!B14,'Data Dashboard'!$B$5:$B$14) -> 10
A44: Spearman rho | B44: =CORREL(B34:B43,C34:C43) -> -0.109423
A45: n | B45: =COUNT(B34:B43) -> 10
A46: t-statistic | B46: =B44*SQRT(B45-2)/SQRT(1-B44^2) -> -0.31136463
...

Sheet 3. Probability & Distributions
A1: Probability & Distributions
A4: 3.1 Conditional Probability: P(Above-median Playoff Appearances | Top-50% Auction Spend)
A6: Median 2025 Auction Spend (₹Cr) | B6: =MEDIAN('Data Dashboard'!$P$5:$P$14) -> 119.85
A7: Median Playoff Appearances | B7: =MEDIAN('Data Dashboard'!$E$5:$E$14) -> 7.5
A9: Contingency table (n=10 franchises, live COUNTIFS)
A10: Top-50% 2025 Auction Spend? | B10: Below-median Playoffs | C10: Above-median Playoffs | D10: Total
A11: No | B11: =COUNTIFS('Data Dashboard'!$P$5:$P$14,"<"&$B$6,'Data Dashboard'!$E$5:$E$14,"<"&$B$7) -> 2 | C11: =COUNTIFS('Data Dashboard'!$P$5:$P$14,"<"&$B$6,'Data Dashboard'!$E$5:$E$14,">="&$B$7) -> 2 | D11: =B11+C11 -> 4
A12: Yes | B12: =COUNTIFS('Data Dashboard'!$P$5:$P$14,">="&$B$6,'Data Dashboard'!$E$5:$E$14,"<"&$B$7) -> 3 | C12: =COUNTIFS('Data Dashboard'!$P$5:$P$14,">="&$B$6,'Data Dashboard'!$E$5:$E$14,">="&$B$7) -> 3 | D12: =B12+C12 -> 6
A14: P(Above-median playoffs | Top-50% spend) | B14: =C12/D12 -> 0.5
A16: Interpretation: spending in the top half of the (very narrow) auction band does not meaningfully raise the odds of above-median playoff appearances in this sample — consistent with the weak spend-win correlation in Sheet 2.
A19: 3.2 Normal Distribution Check: Net Run Rate (NRR), 2009-2023 seasons
A20: Sample: n = team-season observations, live-counted from 'Raw NRR Data'.
A21: n | B21: =COUNT('Raw NRR Data'!$D$5:$D$132) -> 128
A22: Mean NRR | B22: =AVERAGE('Raw NRR Data'!$D$5:$D$132) -> -0.0002265625
A23: Std. Deviation (sample) | B23: =_xlfn.STDEV.S('Raw NRR Data'!$D$5:$D$132) -> 0.49077299
A24: Skewness (native SKEW — 0 = symmetric) | B24: =SKEW('Raw NRR Data'!$D$5:$D$132) -> -0.19749105
A25: Excess Kurtosis (native KURT — 0 = normal-like tails) | B25: =KURT('Raw NRR Data'!$D$5:$D$132) -> 0.24317898
A29: Shapiro-Wilk W (Python-computed, not a formula) | B29: 0.9908
A30: p-value (Python-computed, not a formula) | B30: 0.5152
A31: Fail to reject H0 — consistent with Normal (p > 0.05).
A33: Histogram (native FREQUENCY array formula)
A34: Bin upper bound | B34: Frequency
A35: -1.182 | B35: {=FREQUENCY('Raw NRR Data'!$D$5:$D$132,A35:A44)} -> 3
A36: -0.927 | B36: 2
A37: -0.673 | B37: 4
A38: -0.419 | B38: 17
A39: -0.164 | B39: 20
A40: 0.09 | B40: 24
A41: 0.344 | B41: 31
A42: 0.598 | B42: 13
A43: 0.853 | B43: 8
A44: 1.107 | B44: 6

Sheet Raw NRR Data
A1: Raw NRR Data — team-season Net Run Rate, 2009-2023 finals tables
A2: season-by-season points tables
A4: Season (inferred) | B4: Team | C4: Position | D4: NRR
A5: 2023 | B5: Gujarat Titans | C5: 1 Q | D5: 0.809
A6: 2023 | B6: Chennai Super Kings | C6: 2 Q | D6: 0.652
A7: 2023 | B7: Lucknow Super Giants | C7: 3 Q | D7: 0.284
A8: 2023 | B8: Mumbai Indians | C8: 4 Q | D8: -0.044
A9: 2023 | B9: Rajasthan Royals | C9: 5 | D9: 0.148
A10: 2023 | B10: Royal Challengers Bengaluru | C10: 6 | D10: 0.135
A11: 2023 | B11: Kolkata Knight Riders | C11: 7 | D11: -0.239
A12: 2023 | B12: Punjab Kings | C12: 8 | D12: -0.304
A13: 2023 | B13: Delhi Capitals | C13: 9 | D13: -0.808
A14: 2023 | B14: Sunrisers Hyderabad | C14: 10 | D14: -0.59
A15: 2022 | B15: Gujarat Titans | C15: 1 Q | D15: 0.316
A16: 2022 | B16: Rajasthan Royals | C16: 2 Q | D16: 0.298
... A132: 2009 | B132: Kolkata Knight Riders | C132: 8 | D132: -0.789

Sheet 4. Confidence Intervals
A1: Statistical Inference & Confidence Intervals
A4: 95% Confidence Interval — Mean 2025 Franchise Brand Value
A6: Sample size (n) | B6: =COUNT('Data Dashboard'!$B$5:$B$14) -> 10
A7: Sample mean ($M) | B7: =AVERAGE('Data Dashboard'!$B$5:$B$14) -> 183
A8: Sample std. deviation ($M) | B8: =_xlfn.STDEV.S('Data Dashboard'!$B$5:$B$14) -> 53.597264
A9: Standard error of the mean | B9: =$B$8/SQRT($B$6) -> 16.948943
A10: Margin of error @ 95% (CONFIDENCE.T, t-dist, df=n-1) | B10: =_xlfn.CONFIDENCE.T(0.05,$B$8,$B$6) -> 38.341173
A11: 95% CI lower bound ($M) | B11: =$B$7-$B$10 -> 144.65883
A12: 95% CI upper bound ($M) | B12: =$B$7+$B$10 -> 221.34117
A14: Method note
A15: CONFIDENCE.T uses the t-distribution (df = n-1), appropriate for a small sample with unknown population variance. It returns the same margin as MEAN ± T.INV.2T(0.05,n-1)*SEM. With n=10 this interval is wide — read it as a rough planning range, not a precision estimate.
A18: The Pitch
A19: ="If a new franchise is introduced in 2027, we can state with 95% confidence that its baseline brand value will fall between $"&TEXT($B$11,"0")&" Million and $"&TEXT($B$12,"0")&" Million, setting the floor for the BCCI's auction reserve price." -> If a new franchise is introduced in 2027, we can state with 95% confidence that its baseline brand value will fall between $145 Million and $221 Million, setting the floor for the BCCI's auction reserve price.
A23: Caveat for the room: this interval describes the spread of 8 established and 2 new , already-successful franchises. A brand-new 2027 team has no track record, no title equity, and an unknown fanbase — its realistic starting brand value is more likely to sit near the low end of this range (or below it) than the middle.

Sheet 5. Hypothesis Testing
A1: Hypothesis Testing — The Myths
A4: 5.1 Two-Sample t-Test: Legacy (2008) vs. Expansion Franchises — 2025 Brand Value
A5: H0: No difference in brand value based on franchise age (legacy vs. expansion).
A6: Legacy n | B6: =COUNT('Data Dashboard'!$B$5:$B$12) -> 8
A7: Legacy mean Brand Value ($M) | B7: =AVERAGE('Data Dashboard'!$B$5:$B$12) -> 195.75
A8: Expansion n | B8: =COUNT('Data Dashboard'!$B$13:$B$14) -> 2
A9: Expansion mean Brand Value ($M) | B9: =AVERAGE('Data Dashboard'!$B$13:$B$14) -> 132
A10: p-value | B10: =_xlfn.T.TEST('Data Dashboard'!$B$5:$B$12,'Data Dashboard'!$B$13:$B$14,2,3) -> 0.018070804
A12: Conclusion: | B12: =IF($B$10<0.05,"Reject H0 (p < 0.05)","Fail to reject H0 (p >= 0.05)") -> Reject H0 (p < 0.05)
A13: Legacy franchises have a statistically higher mean brand value in this sample. (Note: only n=2 expansion franchises — GT and LSG — treat with real caution.)
A16: 5.2 One-Sample Test: RCB Win% vs. League-Neutral 50%
A17: H0: RCB's all-time (2008-2023) win percentage equals 50%.
A19: RCB win % (2008-2023), as proportion | B19: ='Data Dashboard'!G7/100 -> 0.4825
A20: RCB matches, n | B20: ='Data Dashboard'!H7 -> 228
A21: Hypothesized proportion, p0 | B21: 0.5
A22: Standard error = SQRT(p0*(1-p0)/n) | B22: =SQRT($B$21*(1-$B$21)/$B$20) -> 0.033113309
A23: z-statistic = | B23: =($B$19-$B$21)/$B$22 -> -0.52848841
A24: p-value (two-tailed) = 2*(1-NORM.S.DIST(ABS(z),TRUE)) | B24: =2*(1-_xlfn.NORM.S.DIST(ABS($B$23),TRUE())) -> 0.59716039
A25: Conclusion: | B25: =IF($B$24<0.05,"Reject H0","Fail to reject H0") -> Fail to reject H0
A26: RCB's long-run win rate is statistically indistinguishable from 50%, despite the team's reputation (until 2025) as a chronic underachiever — the 'RCB always chokes' narrative is not supported by the all-time numbers; it's a small-sample recency / finals-drought effect.
A29: 5.3 One-Way ANOVA (F-Test): 2025 Auction Spend across Title Tiers
A30: H0: Mean 2025 auction spend is equal across Zero / Single / Multiple-title tiers.
A32: Tier | B32: n | C32: Mean Spend (₹Cr)
A33: Zero titles | B33: =COUNTIF('Data Dashboard'!$S$5:$S$14,"Zero titles") -> 3 | C33: =AVERAGEIF('Data Dashboard'!$S$5:$S$14,"Zero titles",'Data Dashboard'!$P$5:$P$14) -> 119.73333 | D33: Almost Equal due to fixed purse size.
A34: Single title | B34: =COUNTIF('Data Dashboard'!$S$5:$S$14,"Single title") -> 3 | C34: =AVERAGEIF('Data Dashboard'!$S$5:$S$14,"Single title",'Data Dashboard'!$P$5:$P$14) -> 119.86667
A35: Multiple titles | B35: =COUNTIF('Data Dashboard'!$S$5:$S$14,"Multiple titles") -> 4 | C35: =AVERAGEIF('Data Dashboard'!$S$5:$S$14,"Multiple titles",'Data Dashboard'!$P$5:$P$14) -> 119.85
A36: Grand mean | B36: =AVERAGE('Data Dashboard'!$P$5:$P$14) -> 119.82
A37: Grand n | B37: =COUNT('Data Dashboard'!$P$5:$P$14) -> 10
A38: SSB (between-group sum of squares) | B38: =B33*(C33-$B$36)^2+B34*(C34-$B$36)^2+B35*(C35-$B$36)^2 -> 0.032666667
A39: SSW (within-group sum of squares) | B39: =SUMPRODUCT(('Data Dashboard'!$S$5:$S$14="Zero titles")*('Data Dashboard'!$P$5:$P$14-C33)^2)+SUMPRODUCT(('Data Dashboard'!$S$5:$S$14="Single title")*('Data Dashboard'!$P$5:$P$14-C34)^2)+SUMPRODUCT(('Data Dashboard'!$S$5:$S$14="Multiple titles")*('Data Dashboard'!$P$5:$P$14-C35)^2) -> 0.13333333
A40: df between (k-1) | B40: 2
A41: df within (N-k) | B41: =$B$37-3 -> 7
A42: MSB = SSB/dfB | B42: =$B$38/$B$40 -> 0.016333333
A43: MSW = SSW/dfW | B43: =$B$39/$B$41 -> 0.019047619
A44: F = MSB / MSW | B44: =$B$42/$B$43 -> 0.8575
A45: p-value = F.DIST.RT(F, dfB, dfW) | B45: =_xlfn.F.DIST.RT($B$44,$B$40,$B$41) -> 0.4644161
A46: Conclusion: | B46: =IF($B$45<0.05,"Reject H0","Fail to reject H0") -> Fail to reject H0
A47: No significant difference in auction spend across title tiers. Title-winners don't out-spend everyone else; the hard salary cap means everybody spends roughly the same amount, win or lose.

Sheet Rough for regression
A1: Column1 | C1: Column2 | E1: Column3
A3: Mean | B3: 53.213 | C3: Mean | D3: 15.1737 | E3: Mean | F3: 6565454.8
A4: Standard Error | B4: 2.5549212 | C4: Standard Error | D4: 3.6520606 | E4: Standard Error | F4: 1484696.4
A5: Median | B5: 49.31 | C5: Median | D5: 9.25 | E5: Median | F5: 5112336
A6: Mode | B6: 46.49 | C6: Mode | D6: #N/A | E6: Mode | F6: #N/A
A7: Standard Deviation | B7: 8.0793702 | C7: Standard Deviation | D7: 11.54883 | E7: Standard Deviation | F7: 4695022.3
A8: Sample Variance | B8: 65.276223 | C8: Sample Variance | D8: 133.37546 | E8: Sample Variance | F8: 2.2043234e+13
A9: Kurtosis | B9: 1.7974256 | C9: Kurtosis | D9: -1.039291 | E9: Kurtosis | F9: 0.84571781
A10: Skewness | B10: 1.4469543 | C10: Skewness | D10: 0.94463968 | E10: Skewness | F10: 1.150941
A11: Range | B11: 24.94 | C11: Range | D11: 29.884 | E11: Range | F11: 15289156
A12: Minimum | B12: 46.49 | C12: Minimum | D12: 4.416 | E12: Minimum | F12: 1025682
A13: Maximum | B13: 71.43 | C13: Maximum | D13: 34.3 | E13: Maximum | F13: 16314838
A14: Sum | B14: 532.13 | C14: Sum | D14: 151.737 | E14: Sum | F14: 65654548
A15: Count | B15: 10 | C15: Count | D15: 10 | E15: Count | F15: 10

Sheet 6. Regression Engine
A1: Advanced Regression — The Valuation Engine
A4: 6.1 Simple Linear Regression: Brand Value = β0 + β1(Titles Won)
A5: LINEST(Y, X, TRUE, TRUE) — 5-row stats output. Column order below is Titles, then Intercept (LINEST convention: last X first).
A6: LINEST output row | B6: Titles (β1) | C6: Intercept (β0)
A7: Coefficient | B7: {=LINEST('Data Dashboard'!$B$5:$B$14,'Data Dashboard'!$D$5:$D$14,TRUE(),TRUE())} -> 22.380952 | C7: 142.71429
A8: Standard Error | B8: 5.7939328 | C8: 14.884883
A9: R² / SE(y) | B9: 0.65098152 | C9: 33.584825
A10: F-statistic / df resid | B10: 14.921422 | C10: 8
A11: SS regression / SS resid | B11: 16830.476 | C11: 9023.5238
A13: R-squared = B9 | B13: =B9 -> 0.65098152
A15: 6.2 Multiple Linear Regression: Brand Value = β0 + β1(Win%) + β2(Social Followers) + β3(City Population)
A17: Team | B17: Win% | C17: Social Followers (M) | D17: Population | F17: 2025 Brand Value ($M)
A18: ='Data Dashboard'!A5 -> Chennai Super Kings | B18: ='Data Dashboard'!G5 -> 57 | C18: ='Data Dashboard'!O5 -> 34.3 | D18: ='Data Dashboard'!L5 -> 4646732 | F18: 235
A19: ='Data Dashboard'!A6 -> Mumbai Indians | B19: ='Data Dashboard'!G6 -> 55.7 | C19: ='Data Dashboard'!O6 -> 28.2 | D19: ='Data Dashboard'!L6 -> 12442373 | F19: 242
A20: ='Data Dashboard'!A7 -> Royal Challengers Bengaluru | B20: ='Data Dashboard'!G7 -> 48.25 | C20: ='Data Dashboard'!O7 -> 31.8 | D20: ='Data Dashboard'!L7 -> 8443675 | F20: 269
A21: ='Data Dashboard'!A8 -> Kolkata Knight Riders | B21: ='Data Dashboard'!G8 -> 49.12 | C21: ='Data Dashboard'!O8 -> 13.2 | D21: ='Data Dashboard'!L8 -> 4496694 | F21: 227
A22: ='Data Dashboard'!A9 -> Sunrisers Hyderabad | B22: ='Data Dashboard'!G9 -> 47.44 | C22: ='Data Dashboard'!O9 -> 9.1 | D22: ='Data Dashboard'!L9 -> 6731790 | F22: 154
A23: ='Data Dashboard'!A10 -> Rajasthan Royals | B23: ='Data Dashboard'!G10 -> 49.5 | C23: ='Data Dashboard'!O10 -> 9.4 | D23: ='Data Dashboard'!L10 -> 3073350 | F23: 146
A24: ='Data Dashboard'!A11 -> Delhi Capitals | B24: ='Data Dashboard'!G11 -> 46.49 | C24: ='Data Dashboard'!O11 -> 7.3 | D24: ='Data Dashboard'!L11 -> 16314838 | F24: 152
A25: ='Data Dashboard'!A12 -> Punjab Kings | B25: ='Data Dashboard'!G12 -> 46.49 | C25: ='Data Dashboard'!O12 -> 8.3 | D25: ='Data Dashboard'!L12 -> 1025682 | F25: 141
A26: ='Data Dashboard'!A13 -> Gujarat Titans | B26: ='Data Dashboard'!G13 -> 71.43 | C26: ='Data Dashboard'!O13 -> 5.721 | D26: ='Data Dashboard'!L13 -> 5577940 | F26: 142
A27: ='Data Dashboard'!A14 -> Lucknow Super Giants | B27: ='Data Dashboard'!G14 -> 60.71 | C27: ='Data Dashboard'!O14 -> 4.416 | D27: ='Data Dashboard'!L14 -> 2901474 | F27: 122
B30: Population (β) | C30: Social Followers (β) | D30: Win% (β) | E30: Intercept (β0)
A31: Coefficient | B31: {=LINEST('Data Dashboard'!$B$5:$B$14,B18:D27,TRUE(),TRUE())} -> 8.7606893e-07 | C31: 4.1165218 | D31: -0.59311121 | E31: 146.34657
A32: Standard Error | B32: 1.9017512e-06 | C32: 0.76536304 | D32: 1.0829855 | E32: 62.417962
A33: R² / SE(y) | B33: 0.84462117 | C33: 25.875227 | D33: #N/A | E33: #N/A
A34: F-statistic / df resid | B34: 10.871767 | C34: 6 | D34: #N/A | E34: #N/A
A35: SS regression / SS resid | B35: 21836.836 | C35: 4017.1642 | D35: #N/A | E35: #N/A
A37: R-squared | B37: =B33 -> 0.84462117
A38: 6.3 Hierarchical Regression
A41: Block 1 — The Uncontrollables: City GDP only
A42: Team | B42: City GDP ($B)
A43: ='Data Dashboard'!A5 -> Chennai Super Kings | B43: ='Data Dashboard'!K5 -> 91.53
A44: ='Data Dashboard'!A6 -> Mumbai Indians | B44: ='Data Dashboard'!K6 -> 162.44
A45: ='Data Dashboard'!A7 -> Royal Challengers Bengaluru | B45: ='Data Dashboard'!K7 -> 112.42
A46: ='Data Dashboard'!A8 -> Kolkata Knight Riders | B46: ='Data Dashboard'!K8 -> 75.21
A47: ='Data Dashboard'!A9 -> Sunrisers Hyderabad | B47: ='Data Dashboard'!K9 -> 80.06
A48: ='Data Dashboard'!A10 -> Rajasthan Royals | B48: ='Data Dashboard'!K10 -> 18.13
A49: ='Data Dashboard'!A11 -> Delhi Capitals | B49: ='Data Dashboard'!K11 -> 186.14
A50: ='Data Dashboard'!A12 -> Punjab Kings | B50: ='Data Dashboard'!K12 -> 11.7
...

Sheet 7. Final Recommendation
A1: The Final Recommendation
A4: Business Directive
A5: Top-weighted variable (live lookup)
A6: Max |standardized beta| | B6: {=MAX(ABS('6. Regression Engine'!B139:B142))} -> 0.661258
A7: Top variable name | B7: =INDEX('6. Regression Engine'!A139:A142,MATCH($B$6,'6. Regression Engine'!B139:B142,0)) -> Social Followers
A8: Top variable beta (signed) | B8: =INDEX('6. Regression Engine'!B139:B142,MATCH($B$7,'6. Regression Engine'!A139:A142,0)) -> 0.661258
A11: ="Of the three levers tested — player acquisition (auction spend / win%), off-field digital content (social media), and market expansion (city GDP) — the hierarchical regression points to "&CHAR(34)&$B$7&CHAR(34)&" as carrying the most weight in the final model (standardized beta = "&TEXT($B$8,"0.00")&"). Recommendation: an IPL management board evaluating where to send its next marginal million dollars should prioritize off-field digital content and fan engagement over incremental auction spend." -> Of the three levers tested — player acquisition (auction spend / win%), off-field digital content (social media), and market expansion (city GDP) — the hierarchical regression points to "Social Followers" as carrying the most weight in the final model (standardized beta = 0.66). Recommendation: an IPL management board evaluating where to send its next marginal million dollars should prioritize off-field digital content and fan engagement over incremental auction spend.
A17: Why (key figures pulled live from Sheets 2 and 6)
A18: • Social media followers has the strongest zero-order correlation with brand value of anything tested (see Sheet 2, Correlation Matrix, 'Social Followers' row/column) — ahead of Titles, and far ahead of all-time Win%.
A19: ΔR² (Block 3 vs Block 2, live from Regression Engine) | B19: ='6. Regression Engine'!B110 -> 0.11830538
A20: • In the hierarchical model, adding social media on top of performance and market size still adds the ΔR² shown above — it is not just riding on the coattails of winning.
A21: • Auction spend shows no significant relationship with either win% or title tier (see Sheet 2 §2.2 and Sheet 5 §5.3 p-values) — the hard salary cap has flattened this lever almost to nothing as a differentiator.
A22: • This does NOT mean performance is irrelevant — Titles remains the second-largest standardized beta (see Sheet 6 §6.4) and the partial correlation with brand value survives controlling for market size (Sheet 2 §2.5). It means digital engagement converts into brand value at least as efficiently as trophies, and far more efficiently than marginal auction spend, which has essentially no room left to move under the cap.
A24: Limitations in the data
A25: • n = 10. Every statistic in this workbook is descriptive/directional, not a high-power inferential result — say this out loud before anyone quotes a p-value as gospel.
A26: • Correlation, not causation: it's plausible that winning teams simply invest more in content production, so social growth could be partly downstream of on-field success rather than a fully independent lever.
A27: • All-time win% (2008-2023) does not include the 2024-2026 seasons, which weren't in the available data — recent-form effects are not captured here.
A28: • Brand value itself is a third-party estimate (Houlihan Lokey), not an audited financial statement.
